2020-07-22 13:48:15,838 INFO: EY Dashboard startup [in C:\Users\grego\Documents\GitHub\EY-DashboardV2\EYvenv\app\__init__.py:48]
2020-07-22 13:49:23,478 INFO: EY Dashboard startup [in C:\Users\grego\Documents\GitHub\EY-DashboardV2\EYvenv\app\__init__.py:48]
2020-07-22 13:51:29,329 INFO: EY Dashboard startup [in C:\Users\grego\Documents\GitHub\EY-DashboardV2\EYvenv\app\__init__.py:48]
2020-07-22 13:52:01,538 INFO: EY Dashboard startup [in C:\Users\grego\Documents\GitHub\EY-DashboardV2\EYvenv\app\__init__.py:48]
2020-07-22 13:53:54,392 INFO: EY Dashboard startup [in C:\Users\grego\Documents\GitHub\EY-DashboardV2\EYvenv\app\__init__.py:48]
2020-07-22 13:55:34,166 INFO: EY Dashboard startup [in C:\Users\grego\Documents\GitHub\EY-DashboardV2\EYvenv\app\__init__.py:48]
2020-07-22 13:58:15,882 INFO: EY Dashboard startup [in C:\Users\grego\Documents\GitHub\EY-DashboardV2\EYvenv\app\__init__.py:48]
2020-07-22 14:20:14,921 INFO: EY Dashboard startup [in C:\Users\grego\Documents\GitHub\EY-DashboardV2\EYvenv\app\__init__.py:48]
2020-07-22 14:20:39,223 INFO: EY Dashboard startup [in C:\Users\grego\Documents\GitHub\EY-DashboardV2\EYvenv\app\__init__.py:48]
2020-07-22 14:29:12,498 INFO: EY Dashboard startup [in C:\Users\grego\Documents\GitHub\EY-DashboardV2\EYvenv\app\__init__.py:48]
2020-07-22 14:29:29,442 INFO: EY Dashboard startup [in C:\Users\grego\Documents\GitHub\EY-DashboardV2\EYvenv\app\__init__.py:48]
2020-07-22 14:29:41,835 INFO: EY Dashboard startup [in C:\Users\grego\Documents\GitHub\EY-DashboardV2\EYvenv\app\__init__.py:48]
2020-07-22 14:30:06,098 ERROR: Exception on /groups/4/group1 [GET] [in c:\users\grego\onedrive\projects\python projects\ey\eyflask_virtualenv\eyvenv\lib\site-packages\flask\app.py:1891]
Traceback (most recent call last):
  File "c:\users\grego\onedrive\projects\python projects\ey\eyflask_virtualenv\eyvenv\lib\site-packages\flask\app.py", line 2446, in wsgi_app
    response = self.full_dispatch_request()
  File "c:\users\grego\onedrive\projects\python projects\ey\eyflask_virtualenv\eyvenv\lib\site-packages\flask\app.py", line 1951, in full_dispatch_request
    rv = self.handle_user_exception(e)
  File "c:\users\grego\onedrive\projects\python projects\ey\eyflask_virtualenv\eyvenv\lib\site-packages\flask\app.py", line 1820, in handle_user_exception
    reraise(exc_type, exc_value, tb)
  File "c:\users\grego\onedrive\projects\python projects\ey\eyflask_virtualenv\eyvenv\lib\site-packages\flask\_compat.py", line 39, in reraise
    raise value
  File "c:\users\grego\onedrive\projects\python projects\ey\eyflask_virtualenv\eyvenv\lib\site-packages\flask\app.py", line 1949, in full_dispatch_request
    rv = self.dispatch_request()
  File "c:\users\grego\onedrive\projects\python projects\ey\eyflask_virtualenv\eyvenv\lib\site-packages\flask\app.py", line 1935, in dispatch_request
    return self.view_functions[rule.endpoint](**req.view_args)
  File "C:\Users\grego\Documents\GitHub\EY-DashboardV2\EYvenv\app\routes.py", line 99, in groups
    group_companies = pickle.loads(group.companies)
AttributeError: 'NoneType' object has no attribute 'companies'
2020-07-22 14:30:30,602 ERROR: Exception on /groups/1/test [GET] [in c:\users\grego\onedrive\projects\python projects\ey\eyflask_virtualenv\eyvenv\lib\site-packages\flask\app.py:1891]
Traceback (most recent call last):
  File "c:\users\grego\onedrive\projects\python projects\ey\eyflask_virtualenv\eyvenv\lib\site-packages\flask\app.py", line 2446, in wsgi_app
    response = self.full_dispatch_request()
  File "c:\users\grego\onedrive\projects\python projects\ey\eyflask_virtualenv\eyvenv\lib\site-packages\flask\app.py", line 1951, in full_dispatch_request
    rv = self.handle_user_exception(e)
  File "c:\users\grego\onedrive\projects\python projects\ey\eyflask_virtualenv\eyvenv\lib\site-packages\flask\app.py", line 1820, in handle_user_exception
    reraise(exc_type, exc_value, tb)
  File "c:\users\grego\onedrive\projects\python projects\ey\eyflask_virtualenv\eyvenv\lib\site-packages\flask\_compat.py", line 39, in reraise
    raise value
  File "c:\users\grego\onedrive\projects\python projects\ey\eyflask_virtualenv\eyvenv\lib\site-packages\flask\app.py", line 1949, in full_dispatch_request
    rv = self.dispatch_request()
  File "c:\users\grego\onedrive\projects\python projects\ey\eyflask_virtualenv\eyvenv\lib\site-packages\flask\app.py", line 1935, in dispatch_request
    return self.view_functions[rule.endpoint](**req.view_args)
  File "C:\Users\grego\Documents\GitHub\EY-DashboardV2\EYvenv\app\routes.py", line 99, in groups
    group_companies = pickle.loads(group.companies)
TypeError: a bytes-like object is required, not 'NoneType'
2020-07-22 14:31:36,512 INFO: EY Dashboard startup [in C:\Users\grego\Documents\GitHub\EY-DashboardV2\EYvenv\app\__init__.py:48]
2020-07-22 14:33:37,540 INFO: EY Dashboard startup [in C:\Users\grego\Documents\GitHub\EY-DashboardV2\EYvenv\app\__init__.py:48]
2020-07-22 14:35:38,323 INFO: EY Dashboard startup [in C:\Users\grego\Documents\GitHub\EY-DashboardV2\EYvenv\app\__init__.py:48]
2020-07-22 14:36:01,750 ERROR: Exception on /groups/8 [GET] [in c:\users\grego\onedrive\projects\python projects\ey\eyflask_virtualenv\eyvenv\lib\site-packages\flask\app.py:1891]
Traceback (most recent call last):
  File "c:\users\grego\onedrive\projects\python projects\ey\eyflask_virtualenv\eyvenv\lib\site-packages\flask\app.py", line 2446, in wsgi_app
    response = self.full_dispatch_request()
  File "c:\users\grego\onedrive\projects\python projects\ey\eyflask_virtualenv\eyvenv\lib\site-packages\flask\app.py", line 1951, in full_dispatch_request
    rv = self.handle_user_exception(e)
  File "c:\users\grego\onedrive\projects\python projects\ey\eyflask_virtualenv\eyvenv\lib\site-packages\flask\app.py", line 1820, in handle_user_exception
    reraise(exc_type, exc_value, tb)
  File "c:\users\grego\onedrive\projects\python projects\ey\eyflask_virtualenv\eyvenv\lib\site-packages\flask\_compat.py", line 39, in reraise
    raise value
  File "c:\users\grego\onedrive\projects\python projects\ey\eyflask_virtualenv\eyvenv\lib\site-packages\flask\app.py", line 1949, in full_dispatch_request
    rv = self.dispatch_request()
  File "c:\users\grego\onedrive\projects\python projects\ey\eyflask_virtualenv\eyvenv\lib\site-packages\flask\app.py", line 1935, in dispatch_request
    return self.view_functions[rule.endpoint](**req.view_args)
TypeError: groups() got an unexpected keyword argument 'group_id'
2020-07-22 14:36:24,206 INFO: EY Dashboard startup [in C:\Users\grego\Documents\GitHub\EY-DashboardV2\EYvenv\app\__init__.py:48]
2020-07-22 14:36:41,965 ERROR: Exception on /groups/9 [GET] [in c:\users\grego\onedrive\projects\python projects\ey\eyflask_virtualenv\eyvenv\lib\site-packages\flask\app.py:1891]
Traceback (most recent call last):
  File "c:\users\grego\onedrive\projects\python projects\ey\eyflask_virtualenv\eyvenv\lib\site-packages\flask\app.py", line 2446, in wsgi_app
    response = self.full_dispatch_request()
  File "c:\users\grego\onedrive\projects\python projects\ey\eyflask_virtualenv\eyvenv\lib\site-packages\flask\app.py", line 1951, in full_dispatch_request
    rv = self.handle_user_exception(e)
  File "c:\users\grego\onedrive\projects\python projects\ey\eyflask_virtualenv\eyvenv\lib\site-packages\flask\app.py", line 1820, in handle_user_exception
    reraise(exc_type, exc_value, tb)
  File "c:\users\grego\onedrive\projects\python projects\ey\eyflask_virtualenv\eyvenv\lib\site-packages\flask\_compat.py", line 39, in reraise
    raise value
  File "c:\users\grego\onedrive\projects\python projects\ey\eyflask_virtualenv\eyvenv\lib\site-packages\flask\app.py", line 1949, in full_dispatch_request
    rv = self.dispatch_request()
  File "c:\users\grego\onedrive\projects\python projects\ey\eyflask_virtualenv\eyvenv\lib\site-packages\flask\app.py", line 1935, in dispatch_request
    return self.view_functions[rule.endpoint](**req.view_args)
  File "C:\Users\grego\Documents\GitHub\EY-DashboardV2\EYvenv\app\routes.py", line 103, in groups
    title=group_name,
NameError: name 'group_name' is not defined
2020-07-22 14:37:19,402 INFO: EY Dashboard startup [in C:\Users\grego\Documents\GitHub\EY-DashboardV2\EYvenv\app\__init__.py:48]
2020-07-24 20:16:48,703 INFO: EY Dashboard startup [in C:\Users\grego\Documents\GitHub\EY-DashboardV2\EYvenv\app\__init__.py:48]
2020-07-24 20:17:04,483 INFO: EY Dashboard startup [in C:\Users\grego\Documents\GitHub\EY-DashboardV2\EYvenv\app\__init__.py:48]
2020-07-24 20:18:06,824 ERROR: Exception on /groups/4 [GET] [in c:\users\grego\onedrive\projects\python projects\ey\eyflask_virtualenv\eyvenv\lib\site-packages\flask\app.py:1891]
Traceback (most recent call last):
  File "c:\users\grego\onedrive\projects\python projects\ey\eyflask_virtualenv\eyvenv\lib\site-packages\flask\app.py", line 2446, in wsgi_app
    response = self.full_dispatch_request()
  File "c:\users\grego\onedrive\projects\python projects\ey\eyflask_virtualenv\eyvenv\lib\site-packages\flask\app.py", line 1951, in full_dispatch_request
    rv = self.handle_user_exception(e)
  File "c:\users\grego\onedrive\projects\python projects\ey\eyflask_virtualenv\eyvenv\lib\site-packages\flask\app.py", line 1820, in handle_user_exception
    reraise(exc_type, exc_value, tb)
  File "c:\users\grego\onedrive\projects\python projects\ey\eyflask_virtualenv\eyvenv\lib\site-packages\flask\_compat.py", line 39, in reraise
    raise value
  File "c:\users\grego\onedrive\projects\python projects\ey\eyflask_virtualenv\eyvenv\lib\site-packages\flask\app.py", line 1949, in full_dispatch_request
    rv = self.dispatch_request()
  File "c:\users\grego\onedrive\projects\python projects\ey\eyflask_virtualenv\eyvenv\lib\site-packages\flask\app.py", line 1935, in dispatch_request
    return self.view_functions[rule.endpoint](**req.view_args)
  File "C:\Users\grego\Documents\GitHub\EY-DashboardV2\EYvenv\app\routes.py", line 104, in groups
    group_companies = pickle.loads(group.companies)
TypeError: a bytes-like object is required, not 'NoneType'
